<?xml version="1.0" ?>
<robot name="Gripper">
  <!--Generated by CROSS, a ROS Workbench for FreeCAD (https://github.com/galou/freecad.cross)-->
  <link name="Link">
    <visual>
      <!--Gripper_base-->
      <origin rpy="0.0 -0.0 0.0" xyz="0.0 0.0 0.0"/>
      <geometry>
        <mesh filename="package://gripper/meshes/gripper_Gripper_base.dae"/>
      </geometry>
    </visual>
    <collision>
      <!--Gripper_base-->
      <origin rpy="0.0 -0.0 0.0" xyz="0.0 0.0 0.0"/>
      <geometry>
        <mesh filename="package://gripper/meshes/gripper_Gripper_base.dae"/>
      </geometry>
    </collision>
    <inertial>
      <mass value="0.0"/>
      <origin rpy="0.0 -0.0 0.0" xyz="0.0 0.0 0.0"/>
      <inertia ixx="0.0" ixy="0.0" ixz="0.0" iyy="0.0" iyz="0.0" izz="0.0"/>
    </inertial>
  </link>
  <link name="Link001">
    <visual>
      <!--Finger-->
      <origin rpy="0.0 -0.0 0.0" xyz="0.0 0.0 0.0"/>
      <geometry>
        <mesh filename="package://gripper/meshes/gripper_Finger.dae"/>
      </geometry>
    </visual>
    <collision>
      <!--Finger-->
      <origin rpy="0.0 -0.0 0.0" xyz="0.0 0.0 0.0"/>
      <geometry>
        <mesh filename="package://gripper/meshes/gripper_Finger.dae"/>
      </geometry>
    </collision>
    <inertial>
      <mass value="0.0"/>
      <origin rpy="0.0 -0.0 0.0" xyz="0.0 0.0 0.0"/>
      <inertia ixx="0.0" ixy="0.0" ixz="0.0" iyy="0.0" iyz="0.0" izz="0.0"/>
    </inertial>
  </link>
  <joint name="Joint" type="prismatic">
    <parent link="Link"/>
    <child link="Link001"/>
    <origin rpy="0.0 -0.0 0.0" xyz="0.08 0.0 0.056"/>
    <axis xyz="0 0 1"/>
    <limit effort="1000.0" lower="-0.078" upper="0.0" velocity="0.0"/>
  </joint>
</robot>
