<?xml version='1.0' encoding='utf-8'?>
<robot xmlns:xacro="http://www.ros.org/wiki/xacro" name="maciv2">

    <!--Copied Inertia as defined in krytn robot to our 6DOF robot-->
    <xacro:include filename="$(find krytn)/robot_description/magni/inertial.xacro" />

    <xacro:include filename="$(find ur_description)/urdf/ur_macro.xacro" />

    <xacro:arg name="ur_type" default="ur5e"/>

    <xacro:ur_robot name="ur5" tf_prefix="ur5_" parent="world" joint_limits_parameters_file="$(find ur_description)/config/$(arg ur_type)/joint_limits.yaml" kinematics_parameters_file="$(find ur_description)/config/$(arg ur_type)/default_kinematics.yaml" physical_parameters_file="$(find ur_description)/config/$(arg ur_type)/physical_parameters.yaml" visual_parameters_file="$(find ur_description)/config/$(arg ur_type)/visual_parameters.yaml" sim_ignition="true" initial_positions="${dict(shoulder_pan_joint=-0.15,shoulder_lift_joint=0,elbow_joint=0.0,wrist_1_joint=0,wrist_2_joint=0.0,wrist_3_joint=0.0)}">
        <origin xyz="-0.1 0 0.15" rpy="0 0 0" />
    </xacro:ur_robot>
    <link name="world" />

    <!-- Add camera to the robot -->

    <xacro:include filename="$(find realsense2_description)/urdf/_d435i.urdf.xacro" />
    <xacro:sensor_d435i parent="ur5_base_link" name="sensor_d435i" use_nominal_extrinsics="True">
        <origin xyz ="-1 -1 0.5" rpy="0 0 ${pi/4}"/>
    </xacro:sensor_d435i>


    <!-- Added Links generated by the gripper freecad file & add gripper joint to connect it to UR-->

    <joint name="gripper_joint" type="fixed">
        <origin xyz="0.0 0.0 0.0" rpy=" 0.0 ${-pi/2} 0.0" />
        <parent link="ur5_tool0" />
        <child link="Gripper_base_link" />
    </joint>

    <link name="Gripper_base_link">
        <visual>
            <!--Gripper_base-->
            <!--origin rpy="0.0 -0.0 0.0" xyz="0.0 0.0 0.0"/-->
            <geometry>
                <mesh filename="file://$(find maciv2)/robot_description/meshes/gripper_Gripper_base.dae"/>
            </geometry>
        </visual>
        <collision>
            <!--Gripper_base-->
            <!--origin rpy="0.0 -0.0 0.0" xyz="0.0 0.0 0.0"/-->
            <geometry>
                <mesh filename="file://$(find maciv2)/robot_description/meshes/gripper_Gripper_base.dae"/>
            </geometry>
        </collision>
        <!--inertial>
            <mass value="1.0"/>
            <origin rpy="0.0 -0.0 0.0" xyz="0.0 0.0 0.0"/>
            <inertia ixx="0.0" ixy="0.0" ixz="0.0" iyy="0.0" iyz="0.0" izz="0.0"/>
        </inertial-->
    </link>
    <link name="Link001">
        <visual>
            <!--Finger-->
            <origin rpy="0.0 -0.0 0.0" xyz="0.0 0.0 0.0"/>
            <geometry>
                <mesh filename="file://$(find maciv2)/robot_description/meshes/gripper_Finger.dae"/>
            </geometry>
        </visual>
        <collision>
            <!--Finger-->
            <origin rpy="0.0 -0.0 0.0" xyz="0.0 0.0 0.0"/>
            <geometry>
                <mesh filename="file://$(find maciv2)/robot_description/meshes/gripper_Finger.dae"/>
            </geometry>
        </collision>
        <!--Add Inertia for this unfixed link for proper visualisation - See the xacro imported on the top of this file-->
        <xacro:box_inertial x="0.03" y="0.03" z="0.1" mass="1" />
    </link>
    <joint name="finger_joint" type="prismatic">
        <parent link="Gripper_base_link"/>
        <child link="Link001"/>
        <origin rpy="0.0 -0.0 0.0" xyz="0.08 0.0 0.056"/>
        <axis xyz="0 0 1"/>
        <limit effort="1000.0" lower="-0.078" upper="0.0" velocity="10.0"/>
    </joint>

    <!--Ros2 control using the maciv2_moveit package created from moveit assistant-->
    <ros2_control name="maciv2" type="system">

        <!--Use krytn magni as reference to import ros2_control for joints-->
        <hardware>
            <plugin>ign_ros2_control/IgnitionSystem</plugin>
        </hardware>

        <joint name="finger_joint">
            <command_interface name="position"/>
            <state_interface name="position">
                <param name="initial_value">0.0</param>
            </state_interface>
            <state_interface name="velocity"/>
        </joint>

    </ros2_control>


    <gazebo>
        <!--Ros2 plugin to control the joints-->
        <plugin filename="ign_ros2_control-system" name="ign_ros2_control::IgnitionROS2ControlPlugin">
            <parameters>$(find maciv2)/config/ros2_controllers.yaml</parameters>
        </plugin>
        <!--Ros2 plugin to control the sensor-->
        <plugin filename="ignition-gazebo-sensors-system" name="ignition::gazebo::systems::Sensors">
            <render_engine>ogre2</render_engine>
        </plugin>
    </gazebo>

    <!--Sensor configuration-->
    <gazebo reference = "sensor_d435i_link">
        <sensor name="realsense_d435" type="rgbd_camera">
            <topic>realsense</topic>
            <ignition_frame_id>sensor_d435i_link</ignition_frame_id>
            <update_rate>5</update_rate>
            <camera name="camera">
                <horizontal_fov>1.5</horizontal_fov>

                <image>
                    <width>320</width>
                    <height>240</height>
                    <format>R8G8B8</format>
                </image>
                <clip>
                    <near>0.01</near>
                    <far>10</far>
                </clip>
                <depth_camera>
                    <clip>
                        <near>0.1</near>
                        <far>10</far>
                    </clip>
                </depth_camera>
                <noise>
                    <type>gaussian</type>
                    <mean>0</mean>
                    <stddev>0.007</stddev>
                </noise>
            </camera>
        </sensor>
    </gazebo>

</robot>